<?xml version='1.0' encoding='utf-8'?>
<mujoco model="agi_walker">
  <option gravity="0 0 -9.8" timestep="0.001" />
  <default>
    <joint damping="1.0" frictionloss="0.05" />
    <geom friction="0.8 0.005 0.0001" />
  </default>
  <worldbody>
    <geom name="floor" type="plane" size="10 10 0.1" rgba="0.9 0.9 0.9 1" />
    <body name="torso" pos="0 0 1.5">
      <geom type="box" size="0.3 0.2 0.4" mass="5.0" />
      <freejoint name="root" />
      <body name="left_leg" pos="-0.15 0 -0.4">
        <geom type="capsule" size="0.08 0.4" mass="2.0" />
        <joint name="hip_left" type="hinge" axis="0 1 0" range="-45.0 90.0" />
      </body>
      <body name="right_leg" pos="0.15 0 -0.4">
        <geom type="capsule" size="0.08 0.4" mass="2.0" />
        <joint name="hip_right" type="hinge" axis="0 1 0" range="-45.0 90.0" />
      </body>
    </body>
  </worldbody>
  <actuator>
    <motor name="motor_hip_left" joint="hip_left" gear="100" />
    <motor name="motor_hip_right" joint="hip_right" gear="100" />
  </actuator>
</mujoco>